Workbook
Name CatchTypeCode: Codes!$Y$43:$Y$48
Name ClassLimitCode: Codes!$Y$36:$Y$38
Name Content: Codes!$Y$58:$Y$61
Name DataSourceCode: Codes!$U$69:$U$75
Name FlagA2ISO: Codes!$F$3:$F$176
Name FlagA3ISO: Codes!$E$3:$E$176
Name FlagCode: Codes!$B$3:$B$176
Name FlagName: Codes!$A$3:$A$176
Name FleetSuffix: Codes!$D$3:$D$176
Name FleetSuffixes: Codes!$D$3:$D$175
Name FreqTypeCode: Codes!$Y$12:$Y$21
Name GearCode: Codes!$U$3:$U$51
Name idiom: 'ST04-T2SZ'!$R$2
Name LangFieldID: Translation!$I$1
Name LangNameID: Translation!$I$2
Name ProdTypeCode: Codes!$Y$25:$Y$31
Name QuadCode: Codes!$AC$3:$AC$7
Name SampAreaCode: Codes!$P$3:$P$121
Name SampleUnitCode: Codes!$U$56:$U$64
Name SampLocatCode: Codes!$U$80:$U$85
Name SchoolTypeCode: Codes!$Y$3:$Y$7
Name SpeciesCode: Codes!$H$3:$H$223
Name SquareTypeCode: Codes!$AC$12:$AC$17
Name StatusCPC: Codes!$C$3:$C$176
Name Version: Codes!$Y$52:$Y$53

Sheet ST04-T2SZ
A1: =VLOOKUP("T00",tblTrans3Langs[],LangFieldID,FALSE) -> ST04-T2SZ | C1: =VLOOKUP("T00",tblTrans3Langs[],LangNameID,FALSE) -> TASK 2 - SIZE SAMPLING (tunas and sharks) | Q1: =VLOOKUP("tVersion",tblTrans3Langs[],LangFieldID,FALSE) -> Version | R1: =VLOOKUP("tLang",tblTrans3Langs[],LangFieldID,FALSE) -> Language
C2: =VLOOKUP("T01",tblTrans3Langs[],LangFieldID,FALSE)&": "&VLOOKUP("T01",tblTrans3Langs[],LangNameID,FALSE) -> ICCAT: INTERNATIONAL COMMISSION FOR THE CONSERVATION OF ATLANTIC TUNAS | Q2: 2026b | R2: ENG
A4: =VLOOKUP("H10",tblTrans3Langs[],LangFieldID,FALSE) -> Statistical Correspondent | J4: =IF(AND(C5>0,C6>0,G6>0,C7>0,C8>0,C9>0,G9>0),"ok","inc") -> inc | K4: =VLOOKUP("H20",tblTrans3Langs[],LangFieldID,FALSE) -> Secretariat use only | Q4: =VLOOKUP("H21",tblTrans3Langs[],LangFieldID,FALSE) -> Filtering criteria
A5: =VLOOKUP("H11",tblTrans3Langs[],LangFieldID,FALSE) -> Identification | B5: =VLOOKUP("hName",tblTrans3Langs[],LangFieldID,FALSE) -> Name | K5: =VLOOKUP("hDaterep",tblTrans3Langs[],LangFieldID,FALSE) -> Date reported | Q5: =VLOOKUP("hFilter1",tblTrans3Langs[],LangFieldID,FALSE) -> Filter 1 | R5: =VLOOKUP("hFilter2",tblTrans3Langs[],LangFieldID,FALSE) -> Filter 2
B6: =VLOOKUP("hEmail",tblTrans3Langs[],LangFieldID,FALSE) -> E-mail | F6: =VLOOKUP("hPhone",tblTrans3Langs[],LangFieldID,FALSE) -> Phone | K6: =VLOOKUP("hRef",tblTrans3Langs[],LangFieldID,FALSE) -> Reference Nº | P6: a) | Q6: 0 | R6: 0
A7: =VLOOKUP("H12",tblTrans3Langs[],LangFieldID,FALSE) -> Affiliation | B7: =VLOOKUP("hInstit",tblTrans3Langs[],LangFieldID,FALSE) -> Institution | K7: id | P7: b) | Q7: 0 | R7: 0
B8: =VLOOKUP("hDepart",tblTrans3Langs[],LangFieldID,FALSE) -> Department | K8: =VLOOKUP("hFname",tblTrans3Langs[],LangFieldID,FALSE) -> File name (proposed) | P8: c) | Q8: 0 | R8: 0
B9: =VLOOKUP("hAddress",tblTrans3Langs[],LangFieldID,FALSE) -> Address | F9: =VLOOKUP("hCountry",tblTrans3Langs[],LangFieldID,FALSE) -> Country | K9: =IF(AND(J4="ok",J11="ok"),"ST04_"&E12&"-"&C14&C13&"-"&RIGHT(E13,2)&LEFT(C17,1)&"-"&LEFT(C19,2)&"#"&M6&".xlsx","") | P9: d)
A11: =VLOOKUP("H30",tblTrans3Langs[],LangFieldID,FALSE) -> Data set characteristics | J11: =IF(E12="","inc",IF(AND(C13>0,E13>0,C14>0,C17>0,C18>0, C15>0,H13>0,H14>0,H15>0,H17>0,H18>0,H19>0),"ok","inc")) -> inc | K11: =VLOOKUP("hNotes",tblTrans3Langs[],LangFieldID,FALSE) -> Notes
A12: =VLOOKUP("hFlagrep",tblTrans3Langs[],LangFieldID,FALSE) -> Reporting Flag | E12: =IFERROR(IF(C12>0,VLOOKUP(C12,Codes!A3:B175,2,FALSE),""),"") | F12: =VLOOKUP("H32",tblTrans3Langs[],LangFieldID,FALSE) -> Sampling attributes
A13: =VLOOKUP("hYearfrom",tblTrans3Langs[#Data],LangFieldID,FALSE) -> Years covered (from) | D13: =VLOOKUP("hYearto",tblTrans3Langs[#Data],LangFieldID,FALSE) -> (to) | F13: =VLOOKUP("hLocationCd",tblTrans3Langs[],LangFieldID,FALSE) -> Location (cod) | I13: =IF(H13>0,VLOOKUP(H13,Codes!U80:V85,2,FALSE),"")
B14: =VLOOKUP("hSpeciesCd",tblTrans3Langs[],LangFieldID,FALSE) -> Species (cod) | D14: =IF(C14>0,VLOOKUP(C14,Codes!$H$3:$L$109,2,FALSE),"") | F14: =VLOOKUP("hSampunit",tblTrans3Langs[],LangFieldID,FALSE) -> Samp unit (cod) | I14: =IF(H14>0,VLOOKUP(H14,Codes!U56:V64,2,FALSE),"")
A15: =VLOOKUP("H31",tblTrans3Langs[],LangFieldID,FALSE) -> Catch attributes | B15: =VLOOKUP("hProdTypeCd",tblTrans3Langs[],LangFieldID,FALSE) -> Product type | D15: =IF(C15>0,VLOOKUP(C15,Codes!$Y$25:$Z$31,2,FALSE),"") | F15: =VLOOKUP("hRaisedSuYN",tblTrans3Langs[],LangFieldID,FALSE) -> Raised (SU) ?
F16: =VLOOKUP("H33",tblTrans3Langs[],LangFieldID,FALSE) -> Frequency type attributes
A17: =VLOOKUP("hVersion",tblTrans3Langs[],LangFieldID,FALSE) -> Version reported | F17: =VLOOKUP("hFreqType",tblTrans3Langs[],LangFieldID,FALSE) -> Frequency type (cod) | I17: =IF(H17>0,VLOOKUP(H17,Codes!$Y$12:$Z$21,2,FALSE),"")
A18: =VLOOKUP("hContent",tblTrans3Langs[],LangFieldID,FALSE) -> Content (data) | F18: =VLOOKUP("hSzinterval",tblTrans3Langs[],LangFieldID,FALSE) -> Interval | I18: =IF(H17="WGT","kg",IF(H17>0,"cm",""))
C19: =IF(C18>0,VLOOKUP(C18,Codes!$Y$58:$AA$61,3,FALSE)&": "&VLOOKUP(C18,Codes!$Y$58:$AA$61,2,FALSE),"") | G19: =VLOOKUP("hSzclasslim",tblTrans3Langs[],LangFieldID,FALSE) -> Class limit | I19: =IF(H19>0,VLOOKUP(H19,Codes!Y36:Z39,2,FALSE),"")
A21: =VLOOKUP("D10",tblTrans3Langs[],LangFieldID,FALSE) -> Sample attributes | S21: =VLOOKUP("D20",tblTrans3Langs[],LangFieldID,FALSE) -> Size frequency details
A22: =IF(LEN(E12)>0, VLOOKUP("D11",tblTrans3Langs[],LangFieldID,FALSE)& " (" & E12 &")", VLOOKUP("D11",tblTrans3Langs[],LangFieldID,FALSE)) -> Fleet ID | C22: =VLOOKUP("D12",tblTrans3Langs[],LangFieldID,FALSE) -> Catch strata associated to samples | O22: =VLOOKUP("D13",tblTrans3Langs[],LangFieldID,FALSE) -> Sample strata | S22: =VLOOKUP(S$26,tblTrans3Langs[],LangFieldID,FALSE) -> Size class | T22: =VLOOKUP("D21",tblTrans3Langs[],LangFieldID,FALSE) -> Number & Gender
A23: =VLOOKUP(A$26,tblTrans3Langs[],LangFieldID,FALSE) -> Flag of Vessel (cod) | B23: =VLOOKUP(B$26,tblTrans3Langs[],LangFieldID,FALSE) -> Fleet suffix | C23: =VLOOKUP(C$26,tblTrans3Langs[],LangFieldID,FALSE) -> Year (calendar) | D23: =VLOOKUP(D$26,tblTrans3Langs[],LangFieldID,FALSE) -> Month | E23: =VLOOKUP(E$26,tblTrans3Langs[],LangFieldID,FALSE) -> Gear (cod) | F23: =VLOOKUP(F$26,tblTrans3Langs[],LangFieldID,FALSE) -> Catch type (cod) | G23: =VLOOKUP(G$26,tblTrans3Langs[],LangFieldID,FALSE) -> School t. (cod) | H23: =VLOOKUP("D12a",tblTrans3Langs[],LangFieldID,FALSE) -> Geographic area | M23: =VLOOKUP(M$26,tblTrans3Langs[],LangFieldID,FALSE) -> Data source (cod) | N23: =VLOOKUP(N$26,tblTrans3Langs[],LangFieldID,FALSE) -> Total catch (kg) | O23: =VLOOKUP(O$26,tblTrans3Langs[],LangFieldID,FALSE) -> Sample unit ID (SU) | P23: =VLOOKUP(P$26,tblTrans3Langs[],LangFieldID,FALSE) -> Month (sample) | Q23: =VLOOKUP("D13a",tblTrans3Langs[],LangFieldID,FALSE) -> Total fish sampled
H24: =VLOOKUP(H$26,tblTrans3Langs[],LangFieldID,FALSE) -> Sampling area (cod) | I24: =VLOOKUP(I$26,tblTrans3Langs[],LangFieldID,FALSE) -> Square t. (cod) | J24: =VLOOKUP(J$26,tblTrans3Langs[],LangFieldID,FALSE) -> Quad (cod) | K24: =VLOOKUP(K$26,tblTrans3Langs[],LangFieldID,FALSE) -> Lat | L24: =VLOOKUP(L$26,tblTrans3Langs[],LangFieldID,FALSE) -> Lon | Q24: =VLOOKUP(Q$26,tblTrans3Langs[],LangFieldID,FALSE) -> Weight (kg) | R24: =VLOOKUP(R$26,tblTrans3Langs[],LangFieldID,FALSE) -> Number | T24: U | U24: M | V24: F | W24: I
A25: {=IF(SUMPRODUCT(MAX(($A27:W50<>"")*ROW($A27:W50)))=0,"",IF(SUMPRODUCT(MAX(($A27:A50<>"")*ROW($A27:A50))+1)<>SUMPRODUCT(MAX(($C27:$W50<>"")*ROW($C27:$W50))+1),"error",IF(COUNTA($A27:A50)<>IFERROR(MATCH(REPT("z",255),$A27:A50),0),"error","ok")))} | C25: {=IF(SUMPRODUCT(MAX(($A27:$W50<>"")*ROW($A27:$W50)))=0,"",IF(COUNTA(C27:C50)<>IFERROR(MATCH(REPT("z",255),$A27:$A50),0),"error",IF(COUNTA(C27:C50)<IFERROR(MATCH(RANDBETWEEN($C13,$E13),C27:C50,1),"error"),"ok",IF(SUMPRODUCT(MAX(($A27:$A50<>"")*ROW($A27:$A50))+1)<>SUMPRODUCT(MAX(($C27:$W50<>"")*ROW($C27:$W50))+1),"error","ok"))))} | D25: {=IF(SUMPRODUCT(MAX(($A27:$W50<>"")*ROW($A27:$W50)))=0,"",IF(COUNTA(D27:D50)<>IFERROR(MATCH(REPT("z",255),$A27:$A50),0),"error",IF(COUNTA(D27:D50)<IFERROR(MATCH(RANDBETWEEN($C13,$E13),D27:D50,1),"error"),"ok",IF(SUMPRODUCT(MAX(($A27:$A50<>"")*ROW($A27:$A50))+1)<>SUMPRODUCT(MAX(($C27:$W50<>"")*ROW($C27:$W50))+1),"error","ok"))))} | E25: {=IF(SUMPRODUCT(MAX(($A27:$W50<>"")*ROW($A27:$W50)))=0,"",IF(COUNTA(E27:E50)<>IFERROR(MATCH(REPT("z",255),$A27:$A50),0),"error",IF(COUNTA(E27:E50)<IFERROR(MATCH(REPT("z",255),E27:E50,1),"error"),"ok",IF(SUMPRODUCT(MAX(($A27:$A50<>"")*ROW($A27:$A50))+1)<>SUMPRODUCT(MAX(($C27:$W50<>"")*ROW($C27:$W50))+1),"error","ok"))))} | F25: {=IF(SUMPRODUCT(MAX(($A27:$W50<>"")*ROW($A27:$W50)))=0,"",IF(COUNTA(F27:F50)<>IFERROR(MATCH(REPT("z",255),$A27:$A50),0),"error",IF(COUNTA(F27:F50)<IFERROR(MATCH(REPT("z",255),F27:F50,1),"error"),"ok",IF(SUMPRODUCT(MAX(($A27:$A50<>"")*ROW($A27:$A50))+1)<>SUMPRODUCT(MAX(($C27:$W50<>"")*ROW($C27:$W50))+1),"error","ok"))))} | G25: {=IF(SUMPRODUCT(MAX(($A27:$W50<>"")*ROW($A27:$W50)))=0,"",IF(COUNTA(G27:G50)<>IFERROR(MATCH(REPT("z",255),$A27:$A50),0),"error",IF(COUNTA(G27:G50)<IFERROR(MATCH(REPT("z",255),G27:G50,1),"error"),"ok",IF(SUMPRODUCT(MAX(($A27:$A50<>"")*ROW($A27:$A50))+1)<>SUMPRODUCT(MAX(($C27:$W50<>"")*ROW($C27:$W50))+1),"error","ok"))))} | H25: {=IF(SUMPRODUCT(MAX(($A27:$W50<>"")*ROW($A27:$W50)))=0,"",IF(COUNTA(H27:H50)<>IFERROR(MATCH(REPT("z",255),$A27:$A50),0),"error",IF(COUNTA(H27:H50)<IFERROR(MATCH(REPT("z",255),H27:H50,1),"error"),"ok",IF(SUMPRODUCT(MAX(($A27:$A50<>"")*ROW($A27:$A50))+1)<>SUMPRODUCT(MAX(($C27:$W50<>"")*ROW($C27:$W50))+1),"error","ok"))))} | I25: {=IF(SUMPRODUCT(MAX(($A27:$W50<>"")*ROW($A27:$W50)))=0,"",IF(COUNTA(I27:I50)<>IFERROR(MATCH(REPT("z",255),$A27:$A50),0),"error",IF(COUNTA(I27:I50)<IFERROR(MATCH(REPT("z",255),I27:I50,1),"error"),"ok",IF(SUMPRODUCT(MAX(($A27:$A50<>"")*ROW($A27:$A50))+1)<>SUMPRODUCT(MAX(($C27:$W50<>"")*ROW($C27:$W50))+1),"error","ok"))))} | J25: {=IF(SUMPRODUCT(MAX(($A27:$W50<>"")*ROW($A27:$W50)))=0,"",IF(COUNTA(J27:J50)<>IFERROR(MATCH(REPT("z",255),$A27:$A50),0),"error",IF(COUNTA(J27:J50)<IFERROR(MATCH(REPT("z",255),J27:J50,1),"error"),"ok",IF(SUMPRODUCT(MAX(($A27:$A50<>"")*ROW($A27:$A50))+1)<>SUMPRODUCT(MAX(($C27:$W50<>"")*ROW($C27:$W50))+1),"error","ok"))))} | K25: {=IF(SUMPRODUCT(MAX(($A27:$W50<>"")*ROW($A27:$W50)))=0,"",IF(COUNTA(K27:K50)<>IFERROR(MATCH(REPT("z",255),$A27:$A50),0),"error",IF(COUNTA(K27:K50)<IFERROR(MATCH(RANDBETWEEN($C13,$E13),K27:K50,1),"error"),"ok",IF(SUMPRODUCT(MAX(($A27:$A50<>"")*ROW($A27:$A50))+1)<>SUMPRODUCT(MAX(($C27:$W50<>"")*ROW($C27:$W50))+1),"error","ok"))))} | L25: {=IF(SUMPRODUCT(MAX(($A27:$W50<>"")*ROW($A27:$W50)))=0,"",IF(COUNTA(L27:L50)<>IFERROR(MATCH(REPT("z",255),$A27:$A50),0),"error",IF(COUNTA(L27:L50)<IFERROR(MATCH(RANDBETWEEN($C13,$E13),L27:L50,1),"error"),"ok",IF(SUMPRODUCT(MAX(($A27:$A50<>"")*ROW($A27:$A50))+1)<>SUMPRODUCT(MAX(($C27:$W50<>"")*ROW($C27:$W50))+1),"error","ok"))))} | M25: {=IF(SUMPRODUCT(MAX(($A27:$W50<>"")*ROW($A27:$W50)))=0,"",IF(COUNTA(M27:M50)<>IFERROR(MATCH(REPT("z",255),$A27:$A50),0),"error",IF(COUNTA(M27:M50)<IFERROR(MATCH(REPT("z",255),M27:M50,1),"error"),"ok",IF(SUMPRODUCT(MAX(($A27:$A50<>"")*ROW($A27:$A50))+1)<>SUMPRODUCT(MAX(($C27:$W50<>"")*ROW($C27:$W50))+1),"error","ok"))))} | P25: {=IF(SUMPRODUCT(MAX(($A27:$W50<>"")*ROW($A27:$W50)))=0,"",IF(COUNTA(P27:P50)<>IFERROR(MATCH(REPT("z",255),$A27:$A50),0),"error",IF(COUNTA(P27:P50)<IFERROR(MATCH(RANDBETWEEN($C13,$E13),P27:P50,1),"error"),"ok",IF(SUMPRODUCT(MAX(($A27:$A50<>"")*ROW($A27:$A50))+1)<>SUMPRODUCT(MAX(($C27:$W50<>"")*ROW($C27:$W50))+1),"error","ok"))))} | Q25: {=IF(SUMPRODUCT(MAX(($A27:$W50<>"")*ROW($A27:$W50)))=0,"",IF(COUNTA(Q27:Q50)<>IFERROR(MATCH(REPT("z",255),$A27:$A50),0),"error",IF(COUNTA(Q27:Q50)<IFERROR(MATCH(RANDBETWEEN($C13,$E13),Q27:Q50,1),"error"),"ok",IF(SUMPRODUCT(MAX(($A27:$A50<>"")*ROW($A27:$A50))+1)<>SUMPRODUCT(MAX(($C27:$W50<>"")*ROW($C27:$W50))+1),"error","ok"))))} | R25: {=IF(SUMPRODUCT(MAX(($A27:$W50<>"")*ROW($A27:$W50)))=0,"",IF(COUNTA(R27:R50)<>IFERROR(MATCH(REPT("z",255),$A27:$A50),0),"error",IF(COUNTA(R27:R50)<IFERROR(MATCH(RANDBETWEEN($C13,$E13),R27:R50,1),"error"),"ok",IF(SUMPRODUCT(MAX(($A27:$A50<>"")*ROW($A27:$A50))+1)<>SUMPRODUCT(MAX(($C27:$W50<>"")*ROW($C27:$W50))+1),"error","ok"))))} | S25: {=IF(SUMPRODUCT(MAX(($A27:$W50<>"")*ROW($A27:$W50)))=0,"",IF(COUNTA(S27:S50)<>IFERROR(MATCH(REPT("z",255),$A27:$A50),0),"error",IF(COUNTA(S27:S50)<IFERROR(MATCH(RANDBETWEEN($C13,$E13),S27:W50,1),"error"),"ok",IF(SUMPRODUCT(MAX(($A27:$A50<>"")*ROW($A27:$A50))+1)<>SUMPRODUCT(MAX(($C27:$W50<>"")*ROW($C27:$W50))+1),"error","ok"))))}
A26: FlagVesCd | B26: FleetSuffix | C26: YearC | D26: Month | E26: GearCd | F26: CatchTypeCd | G26: SchoolTypCd | H26: SaAreaCd | I26: GeoGridCd | J26: QuadCd | K26: Lat | L26: Lon | M26: DSourceCd | N26: TotCatchW | O26: SampleID | P26: MonthSamp | Q26: FishSaW | R26: FishSaN | S26: szClass | T26: NoUs | U26: NoMs | V26: NoFs | W26: NoIs

Sheet Codes
A1: Table. Reporting Flags, Flags of Vessel / Countries (A2 & A3 ISO 3166) | H1: Table. Species (Tunas & sharks) standard codes (FAO alfa 3) | P1: Table. Sampling Areas (ICCAT Task 2) | U1: Table. Gears | Y1: Table. School types | AB1: Table. Quadrants (identifiers & codes)
A2: FlagName | B2: FlagCode | C2: StatusCPC | D2: FleetSuffix | E2: FlagA3ISO | F2: FlagA2ISO | H2: SpeciesCode | I2: ScieName | J2: CoNameEN | K2: CoNameFR | L2: CoNameES | M2: IccSpcGrp | N2: TaxonType | P2: SampAreaCod | Q2: ATorMD | R2: StockCod | S2: Species | U2: GearCode | V2: GearName | W2: GearGroup | Y2: SchoolTypeCode | Z2: SchoolType | AB2: QuadID | AC2: QuadCod | AD2: Quadrant
A3: Albania | B3: ALB | C3: CP | E3: ALB | F3: AL | H3: BFT | I3: Thunnus thynnus | J3: Northern bluefin tuna | K3: Thon rouge du Nord | L3: Atún rojo | M3: 1-Tuna (major sp.) | N3: 1-Species | P3: AL31 | Q3: AT | R3: ALB-N | S3: ALB | U3: LL | V3: Longline | W3: LL | Y3: UNK | Z3: Unknown | AB3: 0 | AC3: UN | AD3: Unknown (for sampling areas only)
A4: Algerie | B4: DZA | C4: CP | E4: DZA | F4: DZ | H4: YFT | I4: Thunnus albacares | J4: Yellowfin tuna | K4: Albacore | L4: Rabil | M4: 1-Tuna (major sp.) | N4: 1-Species | P4: AL32 | Q4: AT | U4: LL-B | V4: Longline: Bottom or Deep longliners | W4: LL | Y4: FAD | Z4: Fish Aggregating Devices | AB4: 1 | AC4: NE | AD4: Northeast
A5: Angola | B5: AGO | C5: CP | E5: AGO | F5: AO | H5: ALB | I5: Thunnus alalunga | J5: Albacore | K5: Germon | L5: Atún blanco | M5: 1-Tuna (major sp.) | N5: 1-Species | P5: AL33 | Q5: AT | R5: ALB-S | U5: LL-Shrk | V5: Longline: Targetting sharks (BSH & SMA) | W5: LL | Y5: FSC | Z5: Free School | AB5: 2 | AC5: SE | AD5: Southeast
A6: Barbados | B6: BRB | C6: CP | E6: BRB | F6: BB | H6: BET | I6: Thunnus obesus | J6: Bigeye tuna | K6: Thon obèse(=Patudo) | L6: Patudo | M6: 1-Tuna (major sp.) | N6: 1-Species | P6: AL34 | Q6: AT | U6: LL-surf | V6: Longline: Surface | W6: LL | Y6: n/a | Z6: Not Applicable | AB6: 3 | AC6: SW | AD6: Southwest
A7: Belize | B7: BLZ | C7: CP | D7: ETRO, ETRO-FP | E7: BLZ | F7: BZ | H7: SKJ | I7: Katsuwonus pelamis | J7: Skipjack tuna | K7: Listao | L7: Listado | M7: 1-Tuna (major sp.) | N7: 1-Species | P7: AL35 | Q7: MD | R7: ALB-M | U7: LLALB | V7: Longline: Targetting ALB | W7: LL | Y7: OTH | Z7: Other (specified it in notes) | AB7: 4 | AC7: NW | AD7: Northwest
A8: Brazil | B8: BRA | C8: CP | D8: Recreational (or Sport) | E8: BRA | F8: BR | H8: SFA | I8: Istiophorus platypterus | J8: Sailfish | K8: Voilier | L8: Pez vela | M8: 1-Tuna (major sp.) | N8: 1-Species | P8: BF53 | Q8: AT | R8: BFT-E | S8: BFT | U8: LLAMS | V8: Longline: American style | W8: LL
A9: Cabo Verde | B9: CPV | C9: CP | D9: Artisanal, Industrial, ETRO, ETRO-FP | E9: CPV | F9: CV | H9: BUM | I9: Makaira nigricans | J9: Blue marlin | K9: Makaire bleu | L9: Aguja azul | M9: 1-Tuna (major sp.) | N9: 1-Species | P9: BF54 | Q9: AT | U9: LLBFT | V9: Longline: Targetting BFT | W9: LL
A10: Canada | B10: CAN | C10: CP | E10: CAN | F10: CA | H10: WHM | I10: Kajikia albida | J10: Atlantic white marlin | K10: Makaire blanc de l'Atlantique | L10: Aguja blanca del Atlántico | M10: 1-Tuna (major sp.) | N10: 1-Species | P10: BF57 | Q10: AT | U10: LLJAP | V10: Longline: Japanese type (Spain) | W10: LL | Y10: Table. Size/weight frequency types | AB10: Table. Square types (identifiers & codes)
A11: China PR | B11: CHN | C11: CP | E11: CHN | F11: CN | H11: SWO | I11: Xiphias gladius | J11: Swordfish | K11: Espadon | L11: Pez espada | M11: 1-Tuna (major sp.) | N11: 1-Species | P11: BF58 | Q11: AT | U11: LLMB | V11: Longline: With mother boat | W11: LL | Y11: FreqTypeCode | Z11: FreqType | AB11: SquareTypeID | AC11: SquareTypeCod | AD11: SquareType
A12: Costa Rica | B12: CRI | C12: CP | E12: CRI | F12: CR | H12: SPF | I12: Tetrapturus pfluegeri | J12: Longbill spearfish | K12: Makaire bécune | L12: Aguja picuda | M12: 1-Tuna (major sp.) | N12: 1-Species | P12: BF59 | Q12: MD | U12: LLMESO | V12: Longline: Mesopelagic | W12: LL | Y12: SFL | Z12: Straight fork length (old FL) | AB12: 1 | AC12: 5x10 | AD12: Rectangle: 5° latitude by 10° longitude
A13: Cuba | B13: CUB | C13: CP | E13: CUB | F13: CU | H13: BLF | I13: Thunnus atlanticus | J13: Blackfin tuna | K13: Thon à nageoires noires | L13: Atún aleta negra | M13: 2-Tuna (small t.) | N13: 1-Species | P13: BF62 | Q13: AT | U13: LLPB | V13: Longline: "Stone-ball" (Spain) | W13: LL | Y13: CFL | Z13: Curved Fork Length | AB13: 3 | AC13: 10x10 | AD13: Rectangle: 10° latitude by 10° longitude
A14: Curaçao | B14: CUW | C14: CP | D14: ETRO, ETRO-FP | E14: CUW | F14: CW | H14: LTA | I14: Euthynnus alletteratus | J14: Little tunny(=Atl.black skipj) | K14: Thonine commune | L14: Bacoreta | M14: 2-Tuna (small t.) | N14: 1-Species | P14: BF65 | Q14: AT | U14: LLSWO | V14: Longline: Targetting SWO | W14: LL | Y14: LD1 | Z14: Lower Jaw TO 1st Dorsal Length | AB14: 5 | AC14: 1x1 | AD14: Square: 1° latitude by 1° longitude
A15: Côte d'Ivoire | B15: CIV | C15: CP | D15: Artisanal, ETRO, ETRO-FP | E15: CIV | F15: CI | H15: BON | I15: Sarda sarda | J15: Atlantic bonito | K15: Bonite à dos rayé | L15: Bonito del Atlántico | M15: 2-Tuna (small t.) | N15: 1-Species | P15: BF66 | Q15: AT | U15: PS | V15: Purse seine | W15: PS | Y15: SLJFL | Z15: Straight lower jaw fork length (old LJFL) | AB15: 6 | AC15: 5x5 | AD15: Square: 5° latitude by 5° longitude
A16: EU-Austria | B16: EU-AUT | C16: CP | E16: AUT | F16: AT | H16: FRI | I16: Auxis thazard | J16: Frigate tuna | K16: Auxide | L16: Melva | M16: 2-Tuna (small t.) | N16: 1-Species | P16: BF50 | Q16: AT | R16: BFT-W | U16: PSD | V16: Purse seine: Double-boats | W16: PS | Y16: CLJFL | Z16: Curved lower jaw fork length | AB16: 7 | AC16: LatLon | AD16: Exact Lat/Lon position
A17: EU-Belgium | B17: EU-BEL | C17: CP | E17: BEL | F17: BE | H17: BOP | I17: Orcynopsis unicolor | J17: Plain bonito | K17: Palomette | L17: Tasarte | M17: 2-Tuna (small t.) | N17: 1-Species | P17: BF51 | Q17: AT | U17: PSFB | V17: Purse seine: Catching large fish | W17: PS | Y17: EYF | Z17: Posterior edge of eye socket to Fork Length | AB17: 9 | AC17: ICCAT | AD17: ICCAT sampling area
A18: EU-Bulgaria | B18: EU-BGR | C18: CP | E18: BGR | F18: BG | H18: WAH | I18: Acanthocybium solandri | J18: Wahoo | K18: Thazard-bâtard | L18: Peto | M18: 2-Tuna (small t.) | N18: 1-Species | P18: BF52 | Q18: AT | U18: PSFS | V18: Purse seine: Catching small fish | W18: PS | Y18: TLE | Z18: Total length
A19: EU-Croatia | B19: EU-HRV | C19: CP | D19: Recreational (or Sport) | E19: HRV | F19: HR | H19: SSM | I19: Scomberomorus maculatus | J19: Atlantic Spanish mackerel | K19: Thazard atlantique | L19: Carite atlántico | M19: 2-Tuna (small t.) | N19: 1-Species | P19: BF55 | Q19: AT | U19: PSG | V19: Purse seine: Large scale (over 200 MT capacity) | W19: PS | Y19: WGT | Z19: Weight
A20: EU-Cyprus | B20: EU-CYP | C20: CP | D20: Recreational (or Sport) | E20: CYP | F20: CY | H20: KGM | I20: Scomberomorus cavalla | J20: King mackerel | K20: Thazard barré | L20: Carite lucio | M20: 2-Tuna (small t.) | N20: 1-Species | P20: BF56 | Q20: AT | U20: PSLB | V20: Purse seine: Using live bait | W20: PS | Y20: HGTW | Z20: Head and Gutted (WGT)
A21: EU-Czechia | B21: EU-CZE | C21: CP | E21: CZE | F21: CZ | H21: MAW | I21: Scomberomorus tritor | J21: West African Spanish mackerel | K21: Thazard blanc | L21: Carite lusitánico | M21: 2-Tuna (small t.) | N21: 1-Species | P21: BF60 | Q21: AT | U21: PSM | V21: Purse seine: Medium scale (between 50 and 200 MT capacity) | W21: PS | Y21: OTH | Z21: Other (specified it in notes)
A22: EU-Denmark | B22: EU-DNK | C22: CP | E22: DNK | F22: DK | H22: CER | I22: Scomberomorus regalis | J22: Cero | K22: Thazard franc | L22: Carite chinigua | M22: 2-Tuna (small t.) | N22: 1-Species | P22: BF61 | Q22: AT | U22: PSS | V22: Purse seine: Small scale (less than 50 MT capacity) | W22: PS
A23: EU-España | B23: EU-ESP | C23: CP | D23: Canarias, Coruña, Cantabric sea, ETRO, ETRO-FP, MEDI, Recreational (or Sport) | E23: ESP | F23: ES | H23: BLT | I23: Auxis rochei | J23: Bullet tuna | K23: Bonitou | L23: Melva(=Melvera) | M23: 2-Tuna (small t.) | N23: 1-Species | P23: BF63 | Q23: AT | U23: TRAP | V23: Trap | W23: TP | Y23: Table. Product types (form)
A24: EU-Estonia | B24: EU-EST | C24: CP | E24: EST | F24: EE | H24: BRS | I24: Scomberomorus brasiliensis | J24: Serra Spanish mackerel | K24: Thazard serra | L24: Serra | M24: 2-Tuna (small t.) | N24: 1-Species | P24: BF64 | Q24: AT | U24: TRAP-S | V24: Trap: small traps | W24: TP | Y24: ProdTypeCode | Z24: ProductType
A25: EU-Finland | B25: EU-FIN | C25: CP | E25: FIN | F25: FI | H25: COM | I25: Scomberomorus commerson | J25: Narrow-barred Spanish mackerel | K25: Thazard rayé indo-pacifique | L25: Carite estriado Indo-Pacífico | M25: 2-Tuna (small t.) | N25: 1-Species | P25: BF67 | Q25: AT | U25: TRAPM | V25: Trap: trap non-fixed | W25: TP | Y25: NR | Z25: Number (of fish) | AA25: nr
A26: EU-France | B26: EU-FRA | C26: CP | D26: Mainland, ETRO, ETRO-FP, MEDI, Recreational (or Sport), Guadeloupe, Martinique | E26: FRA | F26: FR | H26: SBF | I26: Thunnus maccoyii | J26: Southern bluefin tuna | K26: Thon rouge du Sud | L26: Atún rojo del Sur | M26: 3-Tuna (other sp.) | N26: 1-Species | P26: BF68 | Q26: AT | U26: BB | V26: Baitboat | W26: BB | Y26: LW | Z26: Live (round) weight | AA26: kg
A27: EU-Germany | B27: EU-DEU | C27: CP | E27: DEU | F27: DE | H27: BLM | I27: Istiompax indica | J27: Black marlin | K27: Makaire noir | L27: Aguja negra | M27: 3-Tuna (other sp.) | N27: 1-Species | P27: BE01 | Q27: AT | R27: BET-A | S27: BET | U27: BBALB | V27: Baitboat: Targgetting ALB | W27: BB | Y27: GG | Z27: Gilled & gutted weight | AA27: kg
A28: EU-Greece | B28: EU-GRC | C28: CP | D28: Recreational (or Sport) | E28: GRC | F28: GR | H28: SLT | I28: Allothunnus fallai | J28: Slender tuna | K28: Thon élégant | L28: Atún lanzón | M28: 3-Tuna (other sp.) | N28: 1-Species | P28: BE02 | Q28: AT | U28: BBF | V28: Baitboat: Freezer | W28: BB | Y28: FL | Z28: Fillet (weight) | AA28: kg
A29: EU-Hungary | B29: EU-HUN | C29: CP | E29: HUN | F29: HU | H29: LEC | I29: Lepidocybium flavobrunneum | J29: Escolar | K29: Escolier noir | L29: Escolar negro | M29: 3-Tuna (other sp.) | N29: 1-Species | P29: BE03 | Q29: AT | U29: BBI | V29: Baitboat: Ice-well | W29: BB | Y29: DR | Z29: Dressed weight | AA29: kg
A30: EU-Ireland | B30: EU-IRL | C30: CP | E30: IRL | F30: IE | H30: GES | I30: Gempylus serpens | J30: Snake mackerel | K30: Escolier serpent | L30: Escolar de canal | M30: 3-Tuna (other sp.) | N30: 1-Species | P30: BE04 | Q30: AT | U30: TRAW | V30: Trawl | W30: TW | Y30: BM | Z30: Belly meat (weigth) | AA30: kg
A31: EU-Italy | B31: EU-ITA | C31: CP | D31: Adriatic sea, Ionian sea, Ligurian sea, Sardenha, Strait of Sicily, Tyrrenean sea | E31: ITA | F31: IT | H31: OIL | I31: Ruvettus pretiosus | J31: Oilfish | K31: Rouvet | L31: Escolar clavo | M31: 3-Tuna (other sp.) | N31: 1-Species | P31: BE05 | Q31: AT | U31: TRAWB | V31: Trawl: Bottom paired (old TRBD) | W31: TW | Y31: OT | Z31: Other (specifed it in notes)
A32: EU-Latvia | B32: EU-LVA | C32: CP | E32: LVA | F32: LV | H32: NPH | I32: Scomberomorus niphonius | J32: Japanese Spanish mackerel | K32: Thazard oriental | L32: Carite oriental | M32: 3-Tuna (other sp.) | N32: 1-Species | P32: BE06 | Q32: AT | U32: TRAWP | V32: Trawl: Mid-water pelagic (old MWT) | W32: TW
A33: EU-Lithuania | B33: EU-LTU | C33: CP | E33: LTU | F33: LT | H33: BUK | I33: Gasterochisma melampus | J33: Butterfly kingfish | K33: Thon papillon | L33: Atún chauchera | M33: 3-Tuna (other sp.) | N33: 1-Species | P33: BE07 | Q33: AT | U33: TRAWPP | V33: Trawl: Mid-water pelagic paired (old MWTD) | W33: TW
A34: EU-Luxemburg | B34: EU-LUX | C34: CP | E34: LUX | F34: LU | H34: KAW | I34: Euthynnus affinis | J34: Kawakawa | K34: Thonine orientale | L34: Bacoreta oriental | M34: 3-Tuna (other sp.) | N34: 1-Species | P34: BE08 | Q34: AT | U34: TROL | V34: Trolling lines | W34: TR | Y34: Table. Size class limits (boundaries)
A35: EU-Malta | B35: EU-MLT | C35: CP | D35: Recreational (or Sport) | E35: MLT | F35: MT | H35: MSP | I35: Tetrapturus belone | J35: Mediterranean spearfish | K35: Marlin de la Méditerranée | L35: Marlín del Mediterráneo | M35: 3-Tuna (other sp.) | N35: 1-Species | P35: BE09 | Q35: AT | U35: TPL | V35: Trapline | W35: TT | Y35: ClassLimitCode | Z35: ClassLimit
A36: EU-Netherlands | B36: EU-NLD | C36: CP | E36: NLD | F36: NL | H36: MLS | I36: Kajikia audax | J36: Striped marlin | K36: Marlin rayé | L36: Marlín rayado | M36: 3-Tuna (other sp.) | N36: 1-Species | P36: BE10 | Q36: AT | U36: GILL | V36: Gillnet: Drift net | W36: GN | Y36: LL | Z36: lower limit
A37: EU-Poland | B37: EU-POL | C37: CP | E37: POL | F37: PL | H37: SSP | I37: Tetrapturus angustirostris | J37: Shortbill spearfish | K37: Makaire à rostre court | L37: Marlín trompa corta | M37: 3-Tuna (other sp.) | N37: 1-Species | P37: BE20 | Q37: MD | U37: GILLALB | V37: Gillnet: Targetting ALB | W37: GN | Y37: UL | Z37: upper limit
A38: EU-Portugal | B38: EU-PRT | C38: CP | D38: Mainland, Azores, Madeira, Recreational (or Sport) | E38: PRT | F38: PT | H38: RSP | I38: Tetrapturus georgii | J38: Roundscale spearfish | K38: Makaire épée | L38: Marlín peto | M38: 3-Tuna (other sp.) | N38: 1-Species | P38: BE30 | Q38: AT | U38: GILLSWO | V38: Gillnet: Targetting SWO | W38: GN | Y38: CP | Z38: central point
A39: EU-Rumania | B39: EU-ROU | C39: CP | E39: ROU | F39: RO | H39: TUS | I39: Thunnus spp | J39: True tunas NEI | K39: Thons Thunnus NCA | L39: Atunes verdaderos NEP | M39: 3-Tuna (other sp.) | N39: 2-Genus | P39: BE40 | Q39: AT | U39: GNS | V39: Gillnet: anchored (set gillnet, FAO) | W39: GN
A40: EU-Slovakia | B40: EU-SVK | C40: CP | E40: SVK | F40: SK | H40: TUN | I40: Thunnini | J40: Tunas NEI | K40: Thonidés NCA | L40: Atunes NEP | M40: 3-Tuna (other sp.) | N40: 3-Tribe | P40: SJ01 | Q40: AT | R40: SKJ-E | S40: SKJ | U40: RR | V40: Rod and Reel | W40: RR
...

Sheet Instructions
A1: =VLOOKUP("G00",tblTrans3Langs[],LangNameID,FALSE) &" ( "&idiom&" )" -> Instructions to complete the form ( ENG )
A2: =VLOOKUP("G01",tblTrans3Langs[],LangFieldID,FALSE) -> General
A3: a) | B3: =VLOOKUP("G01a",tblTrans3Langs[],LangNameID,FALSE) -> Complete as far as possible the Header and Detail sections (don't leave fields empty when information is known)
A4: b) | B4: =VLOOKUP("G01b",tblTrans3Langs[],LangNameID,FALSE) -> In Header section, only white cells can be filled (manually or by selecting from the Combo Box the corresponding code)
A5: c) | B5: =VLOOKUP("G01c",tblTrans3Langs[],LangNameID,FALSE) -> Always use ICCAT standard codes (when element "OTHERS" of various fields is required it must be explicitly described in "Notes")
A6: d) | B6: =VLOOKUP("G01d",tblTrans3Langs[],LangNameID,FALSE) -> Recommendation for users with databases: To paste an entire dataset into the Detail section (must have the same structure and format) use "Paste special (values)"
A7: e) | B7: =VLOOKUP("G01e",tblTrans3Langs[],LangNameID,FALSE) -> Leave "blank" the fields for which you don't collect information
A9: =VLOOKUP("S00",tblTrans3Langs[],LangFieldID,FALSE) -> Specific (by field)
A10: =VLOOKUP("SC01",tblTrans3Langs[],LangFieldID,FALSE) -> Form | B10: =VLOOKUP("SC02",tblTrans3Langs[],LangFieldID,FALSE) -> Sub-form | C10: =VLOOKUP("SC03",tblTrans3Langs[],LangFieldID,FALSE) -> Part | D10: =VLOOKUP("SC04",tblTrans3Langs[],LangFieldID,FALSE) -> Section | E10: =VLOOKUP("SC05",tblTrans3Langs[],LangFieldID,FALSE) -> Sub-section | F10: =VLOOKUP("SC06",tblTrans3Langs[],LangFieldID,FALSE) -> Field (name) | G10: =VLOOKUP("SC07",tblTrans3Langs[],LangFieldID,FALSE) -> Field (format) | H10: =VLOOKUP("SC08",tblTrans3Langs[],LangFieldID,FALSE) -> Description
A11: =VLOOKUP("T00",tblTrans3Langs[],LangFieldID,FALSE) -> ST04-T2SZ | B11: =VLOOKUP("T03",tblTrans3Langs[],LangFieldID,FALSE) -> ST04A | C11: =VLOOKUP("T02",tblTrans3Langs[],LangFieldID,FALSE) -> Title | F11: =VLOOKUP("tVersion",tblTrans3Langs[],LangFieldID,FALSE) -> Version | G11: =VLOOKUP("tVersion",tblTrans3Langs[],7,FALSE) -> (fixed) | H11: =VLOOKUP("tVersion",tblTrans3Langs[],LangNameID,FALSE) -> Always use the lastest version of this form
F12: =VLOOKUP("tLang",tblTrans3Langs[],LangFieldID,FALSE) -> Language | G12: =VLOOKUP("tLang",tblTrans3Langs[],7,FALSE) -> ICCAT code | H12: =VLOOKUP("tLang",tblTrans3Langs[],LangNameID,FALSE) -> Choose the language (ENG, FRA, ESP) for form translation
C13: =VLOOKUP("H00",tblTrans3Langs[],LangFieldID,FALSE) -> Header | D13: =VLOOKUP("H10",tblTrans3Langs[],LangFieldID,FALSE) -> Statistical Correspondent | E13: =VLOOKUP("H11",tblTrans3Langs[],LangFieldID,FALSE) -> Identification | F13: =VLOOKUP("hName",tblTrans3Langs[],LangFieldID,FALSE) -> Name | G13: =VLOOKUP("hName",tblTrans3Langs[],7,FALSE) -> string | H13: =VLOOKUP("hName",tblTrans3Langs[],LangNameID,FALSE) -> Name (full OR Name & Surname) of the Statistical Correspondent (officially nominated by the CPC)
F14: =VLOOKUP("hEmail",tblTrans3Langs[],LangFieldID,FALSE) -> E-mail | G14: =VLOOKUP("hEmail",tblTrans3Langs[],7,FALSE) -> string | H14: =VLOOKUP("hEmail",tblTrans3Langs[],LangNameID,FALSE) -> Email address of the Statistical Correspondent
F15: =VLOOKUP("hPhone",tblTrans3Langs[],LangFieldID,FALSE) -> Phone | G15: =VLOOKUP("hPhone",tblTrans3Langs[],7,FALSE) -> string | H15: =VLOOKUP("hPhone",tblTrans3Langs[],LangNameID,FALSE) -> Telephone number of the Statistical Correspondent
E16: =VLOOKUP("H12",tblTrans3Langs[],LangFieldID,FALSE) -> Affiliation | F16: =VLOOKUP("hInstit",tblTrans3Langs[],LangFieldID,FALSE) -> Institution | G16: =VLOOKUP("hInstit",tblTrans3Langs[],7,FALSE) -> string | H16: =VLOOKUP("hInstit",tblTrans3Langs[],LangNameID,FALSE) -> Institute (ministry, agency, research Institute, etc.) to which the Statistical Correspondent is affiliated
F17: =VLOOKUP("hDepart",tblTrans3Langs[],LangFieldID,FALSE) -> Department | G17: =VLOOKUP("hDepart",tblTrans3Langs[],7,FALSE) -> string | H17: =VLOOKUP("hDepart",tblTrans3Langs[],LangNameID,FALSE) -> Department within the Institution, where applicable
F18: =VLOOKUP("hAddress",tblTrans3Langs[],LangFieldID,FALSE) -> Address | G18: =VLOOKUP("hAddress",tblTrans3Langs[],7,FALSE) -> string | H18: =VLOOKUP("hAddress",tblTrans3Langs[],LangNameID,FALSE) -> Postal address of the institution (street, number, city, state)
F19: =VLOOKUP("hCountry",tblTrans3Langs[],LangFieldID,FALSE) -> Country | G19: =VLOOKUP("hCountry",tblTrans3Langs[],7,FALSE) -> ICCAT code | H19: =VLOOKUP("hCountry",tblTrans3Langs[],LangNameID,FALSE) -> Country in which the Institution is based
D20: =VLOOKUP("H20",tblTrans3Langs[],LangFieldID,FALSE) -> Secretariat use only | F20: =VLOOKUP("hDaterep",tblTrans3Langs[],LangFieldID,FALSE) -> Date reported | G20: =VLOOKUP("hDaterep",tblTrans3Langs[],7,FALSE) -> date | H20: =VLOOKUP("hDaterep",tblTrans3Langs[],LangNameID,FALSE) -> Secretariat use only
F21: =VLOOKUP("hRef",tblTrans3Langs[],LangFieldID,FALSE) -> Reference Nº | G21: =VLOOKUP("hRef",tblTrans3Langs[],7,FALSE) -> ICCAT code | H21: =VLOOKUP("hRef",tblTrans3Langs[],LangNameID,FALSE) -> Secretariat use only
F22: =VLOOKUP("hFname",tblTrans3Langs[],LangFieldID,FALSE) -> File name (proposed) | G22: =VLOOKUP("hFname",tblTrans3Langs[],7,FALSE) -> string | H22: =VLOOKUP("hFname",tblTrans3Langs[],LangNameID,FALSE) -> Send the form to ICCAT with the proposed file name (if required, suffix it with an ID at the end)
E23: =VLOOKUP("H21",tblTrans3Langs[],LangFieldID,FALSE) -> Filtering criteria | F23: =VLOOKUP("hFilter1",tblTrans3Langs[],LangFieldID,FALSE) -> Filter 1 | G23: =VLOOKUP("hFilter1",tblTrans3Langs[],7,FALSE) -> boolean | H23: =VLOOKUP("hFilter1",tblTrans3Langs[],LangNameID,FALSE) -> Secretariat use only
F24: =VLOOKUP("hFilter2",tblTrans3Langs[],LangFieldID,FALSE) -> Filter 2 | G24: =VLOOKUP("hFilter2",tblTrans3Langs[],7,FALSE) -> boolean | H24: =VLOOKUP("hFilter2",tblTrans3Langs[],LangNameID,FALSE) -> Secretariat use only
D25: =VLOOKUP("H30",tblTrans3Langs[],LangFieldID,FALSE) -> Data set characteristics | F25: =VLOOKUP("hFlagrep",tblTrans3Langs[],LangFieldID,FALSE) -> Reporting Flag | G25: =VLOOKUP("hFlagrep",tblTrans3Langs[],7,FALSE) -> ICCAT code | H25: =VLOOKUP("hFlagrep",tblTrans3Langs[],LangNameID,FALSE) -> Choose the Flag CPC reporting the data (ICCAT codes)
F26: =VLOOKUP("hYearFrom",tblTrans3Langs[],LangFieldID,FALSE) -> Years covered (from) | G26: =VLOOKUP("hYearFrom",tblTrans3Langs[],7,FALSE) -> integer | H26: =VLOOKUP("hYearFrom",tblTrans3Langs[],LangNameID,FALSE) -> One or more years can be added to the form. Add the first (from) year (4 digits) to which the data relate
F27: =VLOOKUP("hYearTo",tblTrans3Langs[],LangFieldID,FALSE) -> (to) | G27: =VLOOKUP("hYearTo",tblTrans3Langs[],7,FALSE) -> integer | H27: =VLOOKUP("hYearTo",tblTrans3Langs[],LangNameID,FALSE) -> One or more years can be added to the form. Add the last (to) year (4 digits) to which the data relate
F28: =VLOOKUP("hSpeciesCd",tblTrans3Langs[],LangFieldID,FALSE) -> Species (cod) | G28: =VLOOKUP("hSpeciesCd",tblTrans3Langs[],7,FALSE) -> ICCAT code | H28: =VLOOKUP("hSpeciesCd",tblTrans3Langs[],LangNameID,FALSE) -> BFT only (fixed)
F29: =VLOOKUP("hVersion",tblTrans3Langs[],LangFieldID,FALSE) -> Version reported | G29: =VLOOKUP("hVersion",tblTrans3Langs[],7,FALSE) -> ICCAT code | H29: =VLOOKUP("hVersion",tblTrans3Langs[],LangNameID,FALSE) -> Specify if this submission is Preliminary (subject to revision) or Final (already validated)
F30: =VLOOKUP("hContent",tblTrans3Langs[],LangFieldID,FALSE) -> Content (data) | G30: =VLOOKUP("hContent",tblTrans3Langs[],7,FALSE) -> ICCAT code | H30: =VLOOKUP("hContent",tblTrans3Langs[],LangNameID,FALSE) -> Specify if the overall data content is NEW (full set OR partial set) OR a REVISION (full set OR partial set)
E31: =VLOOKUP("H31",tblTrans3Langs[],LangFieldID,FALSE) -> Catch attributes | F31: =VLOOKUP("hProdTypeCd",tblTrans3Langs[],LangFieldID,FALSE) -> Product type | G31: =VLOOKUP("hProdTypeCd",tblTrans3Langs[],7,FALSE) -> ICCAT code | H31: =VLOOKUP("hProdtypeCd",tblTrans3Langs[],LangNameID,FALSE) -> Choose type of product (round weight, dressed weight, etc.) of the catch reported (ICCAT code)
E32: =VLOOKUP("H32",tblTrans3Langs[],LangFieldID,FALSE) -> Sampling attributes | F32: =VLOOKUP("hLocationCd",tblTrans3Langs[],LangFieldID,FALSE) -> Location (cod) | G32: =VLOOKUP("hLocationCd",tblTrans3Langs[],7,FALSE) -> ICCAT code | H32: =VLOOKUP("hLocationCd",tblTrans3Langs[],LangNameID,FALSE) -> Choose a Location at which the samples were measured (If "other" please specify in notes)
F33: =VLOOKUP("hSampunit",tblTrans3Langs[],LangFieldID,FALSE) -> Samp unit (cod) | G33: =VLOOKUP("hSampunit",tblTrans3Langs[],7,FALSE) -> ICCAT code | H33: =VLOOKUP("hSampunit",tblTrans3Langs[],LangNameID,FALSE) -> Choose a sampling unit (ICCAT codes) in which the data are provided
F34: =VLOOKUP("hRaisedSuYN",tblTrans3Langs[],LangFieldID,FALSE) -> Raised (SU) ? | G34: =VLOOKUP("hRaisedSuYN",tblTrans3Langs[],7,FALSE) -> boolean | H34: =VLOOKUP("hRaisedSuYN",tblTrans3Langs[],LangNameID,FALSE) -> Please choose YES if the size samples have been raised to the Sampling Unit (SU). Otherwise choose NO
E35: =VLOOKUP("H33",tblTrans3Langs[],LangFieldID,FALSE) -> Frequency type attributes | F35: =VLOOKUP("hFreqType",tblTrans3Langs[],LangFieldID,FALSE) -> Frequency type (cod) | G35: =VLOOKUP("hFreqType",tblTrans3Langs[],7,FALSE) -> ICCAT code | H35: =VLOOKUP("hFreqType",tblTrans3Langs[],LangNameID,FALSE) -> Frequencies of the sampling can be of type "size" (1/2/5 cm) OR "weight" (1kg only). Length classes are preferred
F36: =VLOOKUP("hSzinterval",tblTrans3Langs[],LangFieldID,FALSE) -> Interval | G36: =VLOOKUP("hSzinterval",tblTrans3Langs[],7,FALSE) -> integer | H36: =VLOOKUP("hSzinterval",tblTrans3Langs[],LangNameID,FALSE) -> Choose the Interval of the size frequencies (1cm; 2cm, 5 cm; 1kg)
F37: =VLOOKUP("hSzclasslim",tblTrans3Langs[],LangFieldID,FALSE) -> Class limit | G37: =VLOOKUP("hSzclasslim",tblTrans3Langs[],7,FALSE) -> ICCAT code | H37: =VLOOKUP("hSzclasslim",tblTrans3Langs[],LangNameID,FALSE) -> Identify the class boundary intervals (lower limit, central point, upper limit)
D38: =VLOOKUP("H40",tblTrans3Langs[],LangFieldID,FALSE) -> Other attributes | F38: =VLOOKUP("hNotes",tblTrans3Langs[],LangFieldID,FALSE) -> Notes | G38: =VLOOKUP("hNotes",tblTrans3Langs[],7,FALSE) -> string | H38: =VLOOKUP("hNotes",tblTrans3Langs[],LangNameID,FALSE) -> Add additional (complementary) notes in respect to the overall dataset (if needed)
C39: =VLOOKUP("D00",tblTrans3Langs[],LangFieldID,FALSE) -> Detail | D39: =VLOOKUP("D10",tblTrans3Langs[],LangFieldID,FALSE) -> Sample attributes | E39: =VLOOKUP("D11",tblTrans3Langs[],LangFieldID,FALSE) -> Fleet ID | F39: =VLOOKUP("FlagVesCd",tblTrans3Langs[],LangFieldID,FALSE) -> Flag of Vessel (cod) | G39: =VLOOKUP("FlagVesCd",tblTrans3Langs[],7,FALSE) -> ICCAT code | H39: =VLOOKUP("FlagVesCd",tblTrans3Langs[],LangNameID,FALSE) -> Choose the flag of the vessel for which the data apply (whether national or foreign flagged vessel)
F40: =VLOOKUP("FleetSuffix",tblTrans3Langs[],LangFieldID,FALSE) -> Fleet suffix | G40: =VLOOKUP("FleetSuffix",tblTrans3Langs[],7,FALSE) -> string | H40: =VLOOKUP("FleetSuffix",tblTrans3Langs[],LangNameID,FALSE) -> This field should be completed by those CPCs operating various fisheries with an independent data collection system (e.g. Portugal-Azores, Spain-Fuenterrabía, etc.). Additional fleet sufixes (former base ports/zones) can be adopted.
E41: =VLOOKUP("D12",tblTrans3Langs[],LangFieldID,FALSE) -> Catch strata associated to samples | F41: =VLOOKUP("YearC",tblTrans3Langs[],LangFieldID,FALSE) -> Year (calendar) | G41: =VLOOKUP("YearC",tblTrans3Langs[],7,FALSE) -> integer | H41: =VLOOKUP("YearC",tblTrans3Langs[],LangNameID,FALSE) -> Calendar year (four digits) in which the catch was taken
...

Sheet Filters
A1: SCRS Filter criteria for acceptance/rejection of the data reported
A3: =VLOOKUP("SC01",tblTrans3Langs[],LangFieldID,FALSE) -> Form | B3: Filter | C3: Item | D3: Description | E3: Type | F3: Valid set | G3: ="Status ("&LEFT('ST04-T2SZ'!Q2,4)&")" -> Status (2026)
A4: =VLOOKUP("T00",tblTrans3Langs[],LangFieldID,FALSE) -> ST04-T2SZ | B4: 1 | C4: a) | D4: Data must come in one of the valid SCRS electronic forms/Exchange formats | E4: global | F4: ="{"&LEFT('ST04-T2SZ'!Q2,4)&"a}*" -> {2026a}* | G4: In force
C5: b) | D5: Header section must be complete | E5: global | G5: In force
C6: c) | D6: Detail section must be filled-in using ICCAT codes | E6: global | F6: see "codes" sheet | G6: In force
B7: 2 | C7: a) | D7: Proper time resolution (month is mandatory starting with 2017 data) | E7: form specific | F7: {mm} | G7: In force
C8: b) | D8: Proper geographic resolution by gear type (LL/surf) | E8: form specific | F8: {1x1,5x5,5x10,10x10, SA} | G8: In force
C9: c) | D9: Each size class frequency should be a multiple of the interval defined in header section (e.g.: 2 cm classes => 20, 22, 24, 26, …). Classes frequencies with "zero" fish are optional. | E9: form specific | F9: [ClassFreq % Interval = 0] | G9: In force
C10: d) | D10: Size classes within valid ranges [species Working Groups input] and class intervals smaller as possible | E10: form specific | F10: Waiting SCRS | G10: tba
A13: * Suffix "a" refers to the sub-version (revisions with minor corrections & no changes in structure) within a year. Sequentially issued (a,b,...) if required (i.e.: 2025a, 2025b, ...)
A14: SA = Sampling Areas of ICCAT (species based)

Sheet Translation
A1: Translation for Forms | H1: LangFieldID | I1: =IF(idiom="ENG",8,IF(idiom="FRA",9,10)) -> 8
H2: LangNameID | I2: =IF(idiom="ENG",11,IF(idiom="FRA",12,13)) -> 11
A4: FieldID | B4: OrderID | C4: FormID | D4: SubFormID | E4: Section | F4: Item | G4: FieldType | H4: FldNameEN | I4: FldNameFR | J4: FldNameES | K4: FldInstructEN | L4: FldInstructFR | M4: FldInstructES
A5: T00 | B5: 290 | C5: ST04 | D5: ST04 | E5: Titles | F5: title | G5: n/a | H5: ST04-T2SZ | I5: ST04-T2SZ | J5: ST04-T2SZ | K5: TASK 2 - SIZE SAMPLING (tunas and sharks) | L5: TÂCHE 2 - ÉCHANTILLONNAGE DE TAILLE (thonidés et requins) | M5: TAREA 2 - MUESTREO DE TALLAS (túnidos y tiburones)
A6: T01 | B6: 291 | C6: ST04 | D6: ST04 | E6: Titles | F6: subtitle | G6: n/a | H6: ICCAT | I6: CICTA | J6: CICAA | K6: INTERNATIONAL COMMISSION FOR THE CONSERVATION OF ATLANTIC TUNAS | L6: COMMISSION INTERNATIONALE POUR LA CONSERVATION DES THONIDÉS DE L'ATLANTIQUE | M6: COMISIÓN INTERNACIONAL PARA LA CONSERVACIÓN DEL ATÚN ATLÁNTICO
A7: T02 | B7: 292 | C7: ST04 | D7: ST04 | E7: Titles | F7: section | G7: n/a | H7: Title | I7: Titre | J7: Título | K7: Form Title | L7: Titre du formulaire | M7: Título del formulario
A8: T03 | B8: 111 | C8: ST04 | D8: ST04 | E8: Titles | F8: section | G8: n/a | H8: ST04A | I8: ST04A | J8: ST04A | K8: n/a | L8: n/a | M8: n/a
A9: tVersion | B9: 293 | C9: ST04 | D9: ST04 | E9: Titles | F9: field | G9: (fixed) | H9: Version | I9: Version | J9: Versión | K9: Always use the lastest version of this form | L9: Utiliser toujours la dernière version de ce formulaire | M9: Utilice siempre la última versión de este formulario
A10: tLang | B10: 294 | C10: ST04 | D10: ST04 | E10: Titles | F10: field | G10: ICCAT code | H10: Language | I10: Langue | J10: Idioma | K10: Choose the language (ENG, FRA, ESP) for form translation | L10: Choisir la langue (ENG, FRA, ESP) pour la traduction du formulaire | M10: Elija el idioma (ENG, FRA, ESP) para la traducción del formulario
A11: H00 | B11: 295 | C11: ST04 | D11: ST04 | E11: Header | F11: title | G11: n/a | H11: Header | I11: Tête | J11: Cabecera | K11: n/a | L11: n/a | M11: n/a
A12: H10 | B12: 296 | C12: ST04 | D12: ST04 | E12: Header | F12: section | G12: n/a | H12: Statistical Correspondent | I12: Correspondant statistique | J12: Corresponsal estadístico | K12: n/a | L12: n/a | M12: n/a
A13: H11 | B13: 297 | C13: ST04 | D13: ST04 | E13: Header | F13: subsection | G13: n/a | H13: Identification | I13: Identification | J13: Identificación | K13: n/a | L13: n/a | M13: n/a
A14: H12 | B14: 298 | C14: ST04 | D14: ST04 | E14: Header | F14: subsection | G14: n/a | H14: Affiliation | I14: Affiliation | J14: Afiliación | K14: n/a | L14: n/a | M14: n/a
A15: H20 | B15: 299 | C15: ST04 | D15: ST04 | E15: Header | F15: section | G15: n/a | H15: Secretariat use only | I15: Réservé au Secrétariat | J15: Reservado a la Secretaría | K15: n/a | L15: n/a | M15: n/a
A16: H21 | B16: 300 | C16: ST04 | D16: ST04 | E16: Header | F16: subsection | G16: n/a | H16: Filtering criteria | I16: Critères de filtrage | J16: Criterios de filtrado | K16: n/a | L16: n/a | M16: n/a
... A96: SC08 | B96: 380 | C96: ST04 | D96: Instructions | E96: Specific | F96: item | G96: n/a | H96: Description | I96: Description | J96: Descripción | K96: n/a | L96: n/a | M96: n/a
